Workbook

Sheet لوحة التحكم
B2: لوحة تحكم البزنس
B3: ملخص شامل للمبيعات والمصروفات وصافي الربح
B5: المؤشر | C5: القيمة
B6: عدد الطلبات | C6: =COUNTA(الطلبات!D6:D1000) -> 63
B7: إجمالي قيمة الطلبات (بعد الخصم) | C7: =SUM(الطلبات!M6:M1000) -> 108138
B8: إجمالي المبالغ المحصّلة فعليًا | C8: =SUM(الطلبات!N6:N1000) -> 75100
B9: إجمالي المبالغ المتبقية على العملاء | C9: =SUM(الطلبات!O6:O1000) -> 33038
B10: إجمالي تكلفة الإعلانات | C10: =SUM(الإعلانات!F6:F1000) -> 11300
B11: إجمالي رواتب وعمولات الموظفين (شهريًا) | C11: =SUM(الموظفين!H6:H1000) -> 11725
B12: إجمالي المصروفات (إعلانات + رواتب وعمولات) | C12: =C10+C11 -> 23025
B13: صافي الربح / الخسارة (على المحصّل فعليًا) | C13: =C8-C12 -> 52075
B16: ملاحظات:
B17: - كل الأرقام هنا بتتحدث تلقائيًا من شيت (الطلبات) و(الإعلانات) و(الموظفين).
B18: - صافي الربح محسوب على أساس المبالغ اللي اتحصّلت فعليًا (مش كل قيمة الطلبات) عشان يديك صورة حقيقية للكاش.
B19: - لو عاوز تعرف الربح المتوقع بعد تحصيل كل المتبقي، اجمع صافي الربح مع (إجمالي المبالغ المتبقية على العملاء).

Sheet الطلبات
B2: سجل طلبات العملاء
B3: كل طلب = عميل واتساب طلب تنسيق كتب/سلايدات — التاريخ بيتسجل لوحده أول ما تكتب اسم العميل
B5: رقم الطلب | C5: التاريخ | D5: اسم العميل | E5: رقم الواتساب | F5: الموظف المسؤول عن الديل | G5: الكتب/المواد المطلوب تنسيقها | H5: عدد الوحدات المطلوبة (مثلاً عدد الصفوف) | I5: عدد الوحدات المُسلَّمة | J5: المتبقي تسليمه | K5: السعر الأصلي | L5: نسبة الخصم % | M5: السعر بعد الخصم | N5: المبلغ المدفوع | O5: المبلغ المتبقي | P5: حالة الدفع | Q5: حالة التسليم | R5: ملاحظات
C7: =IF(D7="",0,IF(C7=0,TODAY(),C7)) -> 0 | D7: علي البدري | E7: 1015666206 | F7: مهند إبراهيم | G7: المعاصر رياضيات 1ع و2ع و3ع و1ث | H7: 4 | I7: 2 | J7: =IF(H7="","",H7-I7) -> 2 | K7: 2400 | M7: =IF(K7="","",K7*(1-L7)) -> 2400 | N7: 2400 | O7: =IF(M7="","",M7-N7) -> 0 | P7: =IF(K7="","",IF(O7<=0,"مدفوع بالكامل",IF(N7=0,"لم يدفع","دفع جزئي"))) -> مدفوع بالكامل | Q7: =IF(H7="","",IF(J7<=0,"تم التسليم بالكامل",IF(I7=0,"لم يبدأ التنفيذ","تسليم جزئي"))) -> تسليم جزئي | R7: اول وحدة ف 3
C8: =IF(D8="",0,IF(C8=0,TODAY(),C8)) -> 0 | D8: عبد الرحمن لطفي | E8: 1050963072 | F8: مهند إبراهيم | G8: المعاصر رياضيات 1ع و2غ | H8: 2 | I8: 2 | J8: =IF(H8="","",H8-I8) -> 0 | K8: 1200 | M8: =IF(K8="","",K8*(1-L8)) -> 1200 | N8: 1200 | O8: =IF(M8="","",M8-N8) -> 0 | P8: =IF(K8="","",IF(O8<=0,"مدفوع بالكامل",IF(N8=0,"لم يدفع","دفع جزئي"))) -> مدفوع بالكامل | Q8: =IF(H8="","",IF(J8<=0,"تم التسليم بالكامل",IF(I8=0,"لم يبدأ التنفيذ","تسليم جزئي"))) -> تم التسليم بالكامل
C9: =IF(D9="",0,IF(C9=0,TODAY(),C9)) -> 0 | D9: محمد عصام | E9: 1125939533 | F9: مهند إبراهيم | G9: المعاصر رياضيات 1ع و2ع و3ع | H9: 3 | I9: 2 | J9: =IF(H9="","",H9-I9) -> 1 | K9: 1800 | M9: =IF(K9="","",K9*(1-L9)) -> 1800 | N9: 1200 | O9: =IF(M9="","",M9-N9) -> 600 | P9: =IF(K9="","",IF(O9<=0,"مدفوع بالكامل",IF(N9=0,"لم يدفع","دفع جزئي"))) -> دفع جزئي | Q9: =IF(H9="","",IF(J9<=0,"تم التسليم بالكامل",IF(I9=0,"لم يبدأ التنفيذ","تسليم جزئي"))) -> تسليم جزئي
C10: =IF(D10="",0,IF(C10=0,TODAY(),C10)) -> 0 | D10: الدكتور يحي | E10: 11244414831 | F10: مهند إبراهيم | G10: المعاصر رياضيات 1ع و2ع و3ع | H10: 3 | I10: 2 | J10: =IF(H10="","",H10-I10) -> 1 | K10: 1800 | M10: =IF(K10="","",K10*(1-L10)) -> 1800 | N10: 1800 | O10: =IF(M10="","",M10-N10) -> 0 | P10: =IF(K10="","",IF(O10<=0,"مدفوع بالكامل",IF(N10=0,"لم يدفع","دفع جزئي"))) -> مدفوع بالكامل | Q10: =IF(H10="","",IF(J10<=0,"تم التسليم بالكامل",IF(I10=0,"لم يبدأ التنفيذ","تسليم جزئي"))) -> تسليم جزئي | R10: أول وحدة ف 3
C11: =IF(D11="",0,IF(C11=0,TODAY(),C11)) -> 0 | D11: خالد أبو هشة | E11: 1067350572 | F11: مهند إبراهيم | G11: المعاصر رياضيات 1ث و2ث | H11: 2 | J11: =IF(H11="","",H11-I11) -> 2 | K11: 1800 | M11: =IF(K11="","",K11*(1-L11)) -> 1800 | N11: 900 | O11: =IF(M11="","",M11-N11) -> 900 | P11: =IF(K11="","",IF(O11<=0,"مدفوع بالكامل",IF(N11=0,"لم يدفع","دفع جزئي"))) -> دفع جزئي | Q11: =IF(H11="","",IF(J11<=0,"تم التسليم بالكامل",IF(I11=0,"لم يبدأ التنفيذ","تسليم جزئي"))) -> لم يبدأ التنفيذ
C12: =IF(D12="",0,IF(C12=0,TODAY(),C12)) -> 0 | D12: النبيل | E12: 1003882297 | F12: مهند إبراهيم | G12: المعاصر رياضيات 1ع و2ع و3ع | H12: 3 | I12: 2 | J12: =IF(H12="","",H12-I12) -> 1 | K12: 1800 | M12: =IF(K12="","",K12*(1-L12)) -> 1800 | N12: 1800 | O12: =IF(M12="","",M12-N12) -> 0 | P12: =IF(K12="","",IF(O12<=0,"مدفوع بالكامل",IF(N12=0,"لم يدفع","دفع جزئي"))) -> مدفوع بالكامل | Q12: =IF(H12="","",IF(J12<=0,"تم التسليم بالكامل",IF(I12=0,"لم يبدأ التنفيذ","تسليم جزئي"))) -> تسليم جزئي | R12: أول وحدة ف 3
C13: =IF(D13="",0,IF(C13=0,TODAY(),C13)) -> 0 | D13: خالد عبدالفتاح | E13: 1009986324 | F13: مهند إبراهيم | G13: المعاصر رياضيات 1ع و2ع | H13: 2 | I13: 2 | J13: =IF(H13="","",H13-I13) -> 0 | K13: 1200 | M13: =IF(K13="","",K13*(1-L13)) -> 1200 | N13: 1200 | O13: =IF(M13="","",M13-N13) -> 0 | P13: =IF(K13="","",IF(O13<=0,"مدفوع بالكامل",IF(N13=0,"لم يدفع","دفع جزئي"))) -> مدفوع بالكامل | Q13: =IF(H13="","",IF(J13<=0,"تم التسليم بالكامل",IF(I13=0,"لم يبدأ التنفيذ","تسليم جزئي"))) -> تم التسليم بالكامل
C14: =IF(D14="",0,IF(C14=0,TODAY(),C14)) -> 0 | D14: محمد عادل - Mr mohamed adel | E14: 1113440686 | F14: مهند إبراهيم | G14: المعاصر ماث 1ع و2ع و3ع | H14: 3 | J14: =IF(H14="","",H14-I14) -> 3 | K14: 1800 | M14: =IF(K14="","",K14*(1-L14)) -> 1800 | N14: 900 | O14: =IF(M14="","",M14-N14) -> 900 | P14: =IF(K14="","",IF(O14<=0,"مدفوع بالكامل",IF(N14=0,"لم يدفع","دفع جزئي"))) -> دفع جزئي | Q14: =IF(H14="","",IF(J14<=0,"تم التسليم بالكامل",IF(I14=0,"لم يبدأ التنفيذ","تسليم جزئي"))) -> لم يبدأ التنفيذ
C15: =IF(D15="",0,IF(C15=0,TODAY(),C15)) -> 0 | D15: سماح رجب | E15: 1157391901 | F15: مهند إبراهيم | G15: المعاصر رياضيات 1ع و2ع و3ع و1ث | H15: 4 | I15: 2 | J15: =IF(H15="","",H15-I15) -> 2 | K15: 2400 | M15: =IF(K15="","",K15*(1-L15)) -> 2400 | N15: 1800 | O15: =IF(M15="","",M15-N15) -> 600 | P15: =IF(K15="","",IF(O15<=0,"مدفوع بالكامل",IF(N15=0,"لم يدفع","دفع جزئي"))) -> دفع جزئي | Q15: =IF(H15="","",IF(J15<=0,"تم التسليم بالكامل",IF(I15=0,"لم يبدأ التنفيذ","تسليم جزئي"))) -> تسليم جزئي | R15: اول وحدة ف 3
C16: =IF(D16="",0,IF(C16=0,TODAY(),C16)) -> 0 | D16: محمود حنفي | E16: 1501519718 | F16: مهند إبراهيم | G16: المعاصر رياضيات 1ع و 2ع | H16: 2 | I16: 1 | J16: =IF(H16="","",H16-I16) -> 1 | K16: 1200 | M16: =IF(K16="","",K16*(1-L16)) -> 1200 | N16: 1200 | O16: =IF(M16="","",M16-N16) -> 0 | P16: =IF(K16="","",IF(O16<=0,"مدفوع بالكامل",IF(N16=0,"لم يدفع","دفع جزئي"))) -> مدفوع بالكامل | Q16: =IF(H16="","",IF(J16<=0,"تم التسليم بالكامل",IF(I16=0,"لم يبدأ التنفيذ","تسليم جزئي"))) -> تسليم جزئي
C17: =IF(D17="",0,IF(C17=0,TODAY(),C17)) -> 0 | D17: محمود أحمد ندا | E17: 1013414152 | F17: مهند إبراهيم | G17: المعاصر رياضيات 1ع و 2ع | H17: 2 | I17: 1 | J17: =IF(H17="","",H17-I17) -> 1 | K17: 1200 | M17: =IF(K17="","",K17*(1-L17)) -> 1200 | N17: 1200 | O17: =IF(M17="","",M17-N17) -> 0 | P17: =IF(K17="","",IF(O17<=0,"مدفوع بالكامل",IF(N17=0,"لم يدفع","دفع جزئي"))) -> مدفوع بالكامل | Q17: =IF(H17="","",IF(J17<=0,"تم التسليم بالكامل",IF(I17=0,"لم يبدأ التنفيذ","تسليم جزئي"))) -> تسليم جزئي
C18: =IF(D18="",0,IF(C18=0,TODAY(),C18)) -> 0 | D18: سامي أبو النصر | E18: 1016610456 | F18: مهند إبراهيم | G18: المعاصر رياضيات 1ع و 2ع و 3ع | H18: 3 | I18: 2 | J18: =IF(H18="","",H18-I18) -> 1 | K18: 2250 | M18: =IF(K18="","",K18*(1-L18)) -> 2250 | N18: 1800 | O18: =IF(M18="","",M18-N18) -> 450 | P18: =IF(K18="","",IF(O18<=0,"مدفوع بالكامل",IF(N18=0,"لم يدفع","دفع جزئي"))) -> دفع جزئي | Q18: =IF(H18="","",IF(J18<=0,"تم التسليم بالكامل",IF(I18=0,"لم يبدأ التنفيذ","تسليم جزئي"))) -> تسليم جزئي | R18: نمسح الصورة ورقم التليفون من الفريم
C19: =IF(D19="",0,IF(C19=0,TODAY(),C19)) -> 0 | D19: تامر شعبان أحمد | E19: 1282568330 | F19: مهند إبراهيم | G19: المعاصر رياضيات 1ع و 2ع و3ع و1ث و2ث | H19: 5 | I19: 2 | J19: =IF(H19="","",H19-I19) -> 3 | K19: 4200 | M19: =IF(K19="","",K19*(1-L19)) -> 4200 | N19: 2400 | O19: =IF(M19="","",M19-N19) -> 1800 | P19: =IF(K19="","",IF(O19<=0,"مدفوع بالكامل",IF(N19=0,"لم يدفع","دفع جزئي"))) -> دفع جزئي | Q19: =IF(H19="","",IF(J19<=0,"تم التسليم بالكامل",IF(I19=0,"لم يبدأ التنفيذ","تسليم جزئي"))) -> تسليم جزئي | R19: اول وحدة ف 3
C20: =IF(D20="",0,IF(C20=0,TODAY(),C20)) -> 0 | D20: أحمد أبو عمر | E20: 1001257825 | F20: مهند إبراهيم | G20: المعاصر رياضيات 1ع و2ع و3ع | H20: 3 | I20: 2 | J20: =IF(H20="","",H20-I20) -> 1 | K20: 1800 | M20: =IF(K20="","",K20*(1-L20)) -> 1800 | N20: 1500 | O20: =IF(M20="","",M20-N20) -> 300 | P20: =IF(K20="","",IF(O20<=0,"مدفوع بالكامل",IF(N20=0,"لم يدفع","دفع جزئي"))) -> دفع جزئي | Q20: =IF(H20="","",IF(J20<=0,"تم التسليم بالكامل",IF(I20=0,"لم يبدأ التنفيذ","تسليم جزئي"))) -> تسليم جزئي | R20: أول وحدة ف 3
C21: =IF(D21="",0,IF(C21=0,TODAY(),C21)) -> 0 | D21: أحمد شهاب | E21: 1005372274 | F21: مهند إبراهيم | G21: المعاصر رياضيات 3ع و1ث | H21: 2 | J21: =IF(H21="","",H21-I21) -> 2 | K21: 1200 | M21: =IF(K21="","",K21*(1-L21)) -> 1200 | N21: 600 | O21: =IF(M21="","",M21-N21) -> 600 | P21: =IF(K21="","",IF(O21<=0,"مدفوع بالكامل",IF(N21=0,"لم يدفع","دفع جزئي"))) -> دفع جزئي | Q21: =IF(H21="","",IF(J21<=0,"تم التسليم بالكامل",IF(I21=0,"لم يبدأ التنفيذ","تسليم جزئي"))) -> لم يبدأ التنفيذ | R21: أول وحدة ف 3
C22: =IF(D22="",0,IF(C22=0,TODAY(),C22)) -> 0 | D22: رضا خيرت علي | E22: 1008901896 | F22: مهند إبراهيم | G22: المعاصر رياضيات 1ع و2ع و3ع و1ث | H22: 4 | I22: 2 | J22: =IF(H22="","",H22-I22) -> 2 | K22: 2400 | M22: =IF(K22="","",K22*(1-L22)) -> 2400 | N22: 2000 | O22: =IF(M22="","",M22-N22) -> 400 | P22: =IF(K22="","",IF(O22<=0,"مدفوع بالكامل",IF(N22=0,"لم يدفع","دفع جزئي"))) -> دفع جزئي | Q22: =IF(H22="","",IF(J22<=0,"تم التسليم بالكامل",IF(I22=0,"لم يبدأ التنفيذ","تسليم جزئي"))) -> تسليم جزئي
C23: =IF(D23="",0,IF(C23=0,TODAY(),C23)) -> 0 | D23: حسين أنور | E23: 1090488380 | F23: مهند إبراهيم | G23: المعاصر رياضيات 1ع و2ع و3ع | H23: 3 | I23: 2 | J23: =IF(H23="","",H23-I23) -> 1 | K23: 1800 | M23: =IF(K23="","",K23*(1-L23)) -> 1800 | N23: 1500 | O23: =IF(M23="","",M23-N23) -> 300 | P23: =IF(K23="","",IF(O23<=0,"مدفوع بالكامل",IF(N23=0,"لم يدفع","دفع جزئي"))) -> دفع جزئي | Q23: =IF(H23="","",IF(J23<=0,"تم التسليم بالكامل",IF(I23=0,"لم يبدأ التنفيذ","تسليم جزئي"))) -> تسليم جزئي
C24: =IF(D24="",0,IF(C24=0,TODAY(),C24)) -> 0 | D24: علاء الغريب | E24: 1026019730 | F24: مهند إبراهيم | G24: المعاصر 1ع و2ع و3ع | H24: 3 | I24: 2 | J24: =IF(H24="","",H24-I24) -> 1 | K24: 1950 | M24: =IF(K24="","",K24*(1-L24)) -> 1950 | N24: 1650 | O24: =IF(M24="","",M24-N24) -> 300 | P24: =IF(K24="","",IF(O24<=0,"مدفوع بالكامل",IF(N24=0,"لم يدفع","دفع جزئي"))) -> دفع جزئي | Q24: =IF(H24="","",IF(J24<=0,"تم التسليم بالكامل",IF(I24=0,"لم يبدأ التنفيذ","تسليم جزئي"))) -> تسليم جزئي | R24: نشيل صورة المستر من 2ع و3ع
C25: =IF(D25="",0,IF(C25=0,TODAY(),C25)) -> 0 | D25: حسام البحيري | E25: 1091891817 | F25: مهند إبراهيم | G25: المعاصر رياضيات 1ع | H25: 1 | I25: 1 | J25: =IF(H25="","",H25-I25) -> 0 | K25: 750 | M25: =IF(K25="","",K25*(1-L25)) -> 750 | N25: 750 | O25: =IF(M25="","",M25-N25) -> 0 | P25: =IF(K25="","",IF(O25<=0,"مدفوع بالكامل",IF(N25=0,"لم يدفع","دفع جزئي"))) -> مدفوع بالكامل | Q25: =IF(H25="","",IF(J25<=0,"تم التسليم بالكامل",IF(I25=0,"لم يبدأ التنفيذ","تسليم جزئي"))) -> تم التسليم بالكامل
C26: =IF(D26="",0,IF(C26=0,TODAY(),C26)) -> 0 | D26: محمود عيسي | E26: 1010050042 | F26: مهند إبراهيم | G26: المعاصر رياضيات 1ع | H26: 1 | I26: 1 | J26: =IF(H26="","",H26-I26) -> 0 | K26: 750 | M26: =IF(K26="","",K26*(1-L26)) -> 750 | N26: 750 | O26: =IF(M26="","",M26-N26) -> 0 | P26: =IF(K26="","",IF(O26<=0,"مدفوع بالكامل",IF(N26=0,"لم يدفع","دفع جزئي"))) -> مدفوع بالكامل | Q26: =IF(H26="","",IF(J26<=0,"تم التسليم بالكامل",IF(I26=0,"لم يبدأ التنفيذ","تسليم جزئي"))) -> تم التسليم بالكامل
C27: =IF(D27="",0,IF(C27=0,TODAY(),C27)) -> 0 | D27: محمد أبو حجازي | E27: 1124283725 | F27: مهند إبراهيم | G27: المعاصر رياضيات 1ع و2ع و3ع | H27: 3 | I27: 2 | J27: =IF(H27="","",H27-I27) -> 1 | K27: 1800 | M27: =IF(K27="","",K27*(1-L27)) -> 1800 | N27: 1500 | O27: =IF(M27="","",M27-N27) -> 300 | P27: =IF(K27="","",IF(O27<=0,"مدفوع بالكامل",IF(N27=0,"لم يدفع","دفع جزئي"))) -> دفع جزئي | Q27: =IF(H27="","",IF(J27<=0,"تم التسليم بالكامل",IF(I27=0,"لم يبدأ التنفيذ","تسليم جزئي"))) -> تسليم جزئي
C28: =IF(D28="",0,IF(C28=0,TODAY(),C28)) -> 0 | D28: محمد عادل النعيمي | E28: 1277986842 | F28: مهند إبراهيم | G28: المعاصر ماث 3ع و1ث | H28: 2 | J28: =IF(H28="","",H28-I28) -> 2 | K28: 1500 | M28: =IF(K28="","",K28*(1-L28)) -> 1500 | N28: 750 | O28: =IF(M28="","",M28-N28) -> 750 | P28: =IF(K28="","",IF(O28<=0,"مدفوع بالكامل",IF(N28=0,"لم يدفع","دفع جزئي"))) -> دفع جزئي | Q28: =IF(H28="","",IF(J28<=0,"تم التسليم بالكامل",IF(I28=0,"لم يبدأ التنفيذ","تسليم جزئي"))) -> لم يبدأ التنفيذ
C29: =IF(D29="",0,IF(C29=0,TODAY(),C29)) -> 0 | D29: إبراهيم نوار | E29: 1555820112 | F29: مهند إبراهيم | G29: المعاصر رياضيات 1ع و2ع و3ع | H29: 3 | I29: 2 | J29: =IF(H29="","",H29-I29) -> 1 | K29: 1950 | M29: =IF(K29="","",K29*(1-L29)) -> 1950 | N29: 1650 | O29: =IF(M29="","",M29-N29) -> 300 | P29: =IF(K29="","",IF(O29<=0,"مدفوع بالكامل",IF(N29=0,"لم يدفع","دفع جزئي"))) -> دفع جزئي | Q29: =IF(H29="","",IF(J29<=0,"تم التسليم بالكامل",IF(I29=0,"لم يبدأ التنفيذ","تسليم جزئي"))) -> تسليم جزئي
C30: =IF(D30="",0,IF(C30=0,TODAY(),C30)) -> 0 | D30: Farghl Ramadan | E30: 1145557336 | F30: مهند إبراهيم | G30: المعاصر ماث 1ع و2ع و3ع | H30: 3 | J30: =IF(H30="","",H30-I30) -> 3 | K30: 1800 | M30: =IF(K30="","",K30*(1-L30)) -> 1800 | N30: 900 | O30: =IF(M30="","",M30-N30) -> 900 | P30: =IF(K30="","",IF(O30<=0,"مدفوع بالكامل",IF(N30=0,"لم يدفع","دفع جزئي"))) -> دفع جزئي | Q30: =IF(H30="","",IF(J30<=0,"تم التسليم بالكامل",IF(I30=0,"لم يبدأ التنفيذ","تسليم جزئي"))) -> لم يبدأ التنفيذ
C31: =IF(D31="",0,IF(C31=0,TODAY(),C31)) -> 0 | D31: Eslam Elsamahy | E31: 1000897389 | F31: مهند إبراهيم | G31: المعاصر ماث 1ع و2ع و3ع | H31: 3 | J31: =IF(H31="","",H31-I31) -> 3 | K31: 1800 | M31: =IF(K31="","",K31*(1-L31)) -> 1800 | N31: 900 | O31: =IF(M31="","",M31-N31) -> 900 | P31: =IF(K31="","",IF(O31<=0,"مدفوع بالكامل",IF(N31=0,"لم يدفع","دفع جزئي"))) -> دفع جزئي | Q31: =IF(H31="","",IF(J31<=0,"تم التسليم بالكامل",IF(I31=0,"لم يبدأ التنفيذ","تسليم جزئي"))) -> لم يبدأ التنفيذ
C32: =IF(D32="",0,IF(C32=0,TODAY(),C32)) -> 0 | D32: المغربي صابر صابر | E32: 1004984605 | F32: مهند إبراهيم | G32: المعاصر رياضيات 1ع و2ع و 3ع | H32: 3 | I32: 2 | J32: =IF(H32="","",H32-I32) -> 1 | K32: 1800 | M32: =IF(K32="","",K32*(1-L32)) -> 1800 | N32: 1500 | O32: =IF(M32="","",M32-N32) -> 300 | P32: =IF(K32="","",IF(O32<=0,"مدفوع بالكامل",IF(N32=0,"لم يدفع","دفع جزئي"))) -> دفع جزئي | Q32: =IF(H32="","",IF(J32<=0,"تم التسليم بالكامل",IF(I32=0,"لم يبدأ التنفيذ","تسليم جزئي"))) -> تسليم جزئي
C33: =IF(D33="",0,IF(C33=0,TODAY(),C33)) -> 0 | D33: مجدي إمام | E33: 1023376696 | F33: مهند إبراهيم | G33: المعاصر رياضيات 1ث و2ث | H33: 2 | J33: =IF(H33="","",H33-I33) -> 2 | K33: 1800 | M33: =IF(K33="","",K33*(1-L33)) -> 1800 | N33: 1100 | O33: =IF(M33="","",M33-N33) -> 700 | P33: =IF(K33="","",IF(O33<=0,"مدفوع بالكامل",IF(N33=0,"لم يدفع","دفع جزئي"))) -> دفع جزئي | Q33: =IF(H33="","",IF(J33<=0,"تم التسليم بالكامل",IF(I33=0,"لم يبدأ التنفيذ","تسليم جزئي"))) -> لم يبدأ التنفيذ
C34: =IF(D34="",0,IF(C34=0,TODAY(),C34)) -> 0 | D34: أحمد رفعت | E34: 1273040764 | F34: مهند إبراهيم | G34: المعاصر رياضيات 1ع و2ع و3ع و1ث | H34: 4 | I34: 1 | J34: =IF(H34="","",H34-I34) -> 3 | K34: 2400 | M34: =IF(K34="","",K34*(1-L34)) -> 2400 | N34: 1200 | O34: =IF(M34="","",M34-N34) -> 1200 | P34: =IF(K34="","",IF(O34<=0,"مدفوع بالكامل",IF(N34=0,"لم يدفع","دفع جزئي"))) -> دفع جزئي | Q34: =IF(H34="","",IF(J34<=0,"تم التسليم بالكامل",IF(I34=0,"لم يبدأ التنفيذ","تسليم جزئي"))) -> تسليم جزئي | R34: تعديل الصورة
C35: =IF(D35="",0,IF(C35=0,TODAY(),C35)) -> 0 | D35: محمود سامح | E35: 1552155051 | F35: مهند إبراهيم | G35: المعاصر رياضيات 3ع و1ث | H35: 2 | J35: =IF(H35="","",H35-I35) -> 2 | K35: 1200 | M35: =IF(K35="","",K35*(1-L35)) -> 1200 | N35: 600 | O35: =IF(M35="","",M35-N35) -> 600 | P35: =IF(K35="","",IF(O35<=0,"مدفوع بالكامل",IF(N35=0,"لم يدفع","دفع جزئي"))) -> دفع جزئي | Q35: =IF(H35="","",IF(J35<=0,"تم التسليم بالكامل",IF(I35=0,"لم يبدأ التنفيذ","تسليم جزئي"))) -> لم يبدأ التنفيذ
C36: =IF(D36="",0,IF(C36=0,TODAY(),C36)) -> 0 | D36: خليل محمود | E36: 1119187715 | F36: مهند إبراهيم | G36: المعاصر رياضيات 1ع و2ع و3ع | H36: 3 | I36: 2 | J36: =IF(H36="","",H36-I36) -> 1 | K36: 1800 | L36: 0.17 | M36: =IF(K36="","",K36*(1-L36)) -> 1494 | N36: 1500 | O36: =IF(M36="","",M36-N36) -> -6 | P36: =IF(K36="","",IF(O36<=0,"مدفوع بالكامل",IF(N36=0,"لم يدفع","دفع جزئي"))) -> مدفوع بالكامل | Q36: =IF(H36="","",IF(J36<=0,"تم التسليم بالكامل",IF(I36=0,"لم يبدأ التنفيذ","تسليم جزئي"))) -> تسليم جزئي
C37: =IF(D37="",0,IF(C37=0,TODAY(),C37)) -> 0 | D37: كيرلس قاصد | E37: 1220598361 | F37: مهند إبراهيم | G37: المعاصر رياضيات 1ع و2ع و3ع و1ث و2ث | H37: 5 | I37: 2 | J37: =IF(H37="","",H37-I37) -> 3 | K37: 3000 | M37: =IF(K37="","",K37*(1-L37)) -> 3000 | N37: 1500 | O37: =IF(M37="","",M37-N37) -> 1500 | P37: =IF(K37="","",IF(O37<=0,"مدفوع بالكامل",IF(N37=0,"لم يدفع","دفع جزئي"))) -> دفع جزئي | Q37: =IF(H37="","",IF(J37<=0,"تم التسليم بالكامل",IF(I37=0,"لم يبدأ التنفيذ","تسليم جزئي"))) -> تسليم جزئي
C38: =IF(D38="",0,IF(C38=0,TODAY(),C38)) -> 0 | D38: محمد وليد محمد | E38: 1010906262 | F38: مهند إبراهيم | G38: المعاصر رياضيات 1ع و2ع و3ع و1ث | H38: 4 | I38: 2 | J38: =IF(H38="","",H38-I38) -> 2 | K38: 2400 | M38: =IF(K38="","",K38*(1-L38)) -> 2400 | N38: 1200 | O38: =IF(M38="","",M38-N38) -> 1200 | P38: =IF(K38="","",IF(O38<=0,"مدفوع بالكامل",IF(N38=0,"لم يدفع","دفع جزئي"))) -> دفع جزئي | Q38: =IF(H38="","",IF(J38<=0,"تم التسليم بالكامل",IF(I38=0,"لم يبدأ التنفيذ","تسليم جزئي"))) -> تسليم جزئي
C39: =IF(D39="",0,IF(C39=0,TODAY(),C39)) -> 0 | D39: عمر المأزون | E39: 1016094888 | F39: مهند إبراهيم | G39: المعاصر رياضيات 3ع 2ث | H39: 2 | J39: =IF(H39="","",H39-I39) -> 2 | K39: 1200 | M39: =IF(K39="","",K39*(1-L39)) -> 1200 | N39: 600 | O39: =IF(M39="","",M39-N39) -> 600 | P39: =IF(K39="","",IF(O39<=0,"مدفوع بالكامل",IF(N39=0,"لم يدفع","دفع جزئي"))) -> دفع جزئي | Q39: =IF(H39="","",IF(J39<=0,"تم التسليم بالكامل",IF(I39=0,"لم يبدأ التنفيذ","تسليم جزئي"))) -> لم يبدأ التنفيذ
C40: =IF(D40="",0,IF(C40=0,TODAY(),C40)) -> 0 | D40: أحمد حلمي مصطفي | E40: 1080467021 | F40: مهند إبراهيم | G40: المعاصر رياضيات 3ع و1ث | H40: 2 | J40: =IF(H40="","",H40-I40) -> 2 | M40: =IF(K40="","",K40*(1-L40)) | O40: =IF(M40="","",M40-N40) | P40: =IF(K40="","",IF(O40<=0,"مدفوع بالكامل",IF(N40=0,"لم يدفع","دفع جزئي"))) | Q40: =IF(H40="","",IF(J40<=0,"تم التسليم بالكامل",IF(I40=0,"لم يبدأ التنفيذ","تسليم جزئي"))) -> لم يبدأ التنفيذ
C41: =IF(D41="",0,IF(C41=0,TODAY(),C41)) -> 0 | D41: أحمد لامي | E41: 201060561257 | F41: مهند إبراهيم | G41: المعاصر رياضيات 1ع و2ع و3ع | H41: 3 | I41: 1 | J41: =IF(H41="","",H41-I41) -> 2 | K41: 1800 | M41: =IF(K41="","",K41*(1-L41)) -> 1800 | N41: 1200 | O41: =IF(M41="","",M41-N41) -> 600 | P41: =IF(K41="","",IF(O41<=0,"مدفوع بالكامل",IF(N41=0,"لم يدفع","دفع جزئي"))) -> دفع جزئي | Q41: =IF(H41="","",IF(J41<=0,"تم التسليم بالكامل",IF(I41=0,"لم يبدأ التنفيذ","تسليم جزئي"))) -> تسليم جزئي
C42: =IF(D42="",0,IF(C42=0,TODAY(),C42)) -> 0 | D42: محمد زيدان | F42: مهند إبراهيم | J42: =IF(H42="","",H42-I42) | M42: =IF(K42="","",K42*(1-L42)) | O42: =IF(M42="","",M42-N42) | P42: =IF(K42="","",IF(O42<=0,"مدفوع بالكامل",IF(N42=0,"لم يدفع","دفع جزئي"))) | Q42: =IF(H42="","",IF(J42<=0,"تم التسليم بالكامل",IF(I42=0,"لم يبدأ التنفيذ","تسليم جزئي"))) | R42: لغي حجز
C43: =IF(D43="",0,IF(C43=0,TODAY(),C43)) -> 0 | D43: أحمد حسين | E43: 1121289958 | F43: مهند إبراهيم | H43: 3 | I43: 2 | J43: =IF(H43="","",H43-I43) -> 1 | K43: 1800 | M43: =IF(K43="","",K43*(1-L43)) -> 1800 | N43: 900 | O43: =IF(M43="","",M43-N43) -> 900 | P43: =IF(K43="","",IF(O43<=0,"مدفوع بالكامل",IF(N43=0,"لم يدفع","دفع جزئي"))) -> دفع جزئي | Q43: =IF(H43="","",IF(J43<=0,"تم التسليم بالكامل",IF(I43=0,"لم يبدأ التنفيذ","تسليم جزئي"))) -> تسليم جزئي
...

Sheet الإعلانات
B2: مصروفات الحملات الإعلانية
B3: سجّل هنا كل مبلغ بتصرفه على الإعلانات الممولة (فيسبوك/انستغرام/تيك توك...)
B5: التاريخ | C5: اسم الحملة | D5: المنصة | E5: المدة (أيام) | F5: المبلغ المصروف | G5: إجمالي المصروف على الإعلانات: | H5: =SUM(F6:F150) -> 11300
B6: 46235 | C6: حملة انستغرام - تنسيق كتب | D6: انستغرام | E6: 7 | F6: 500 | G6: استهداف أولياء أمور طلبة الثانوية
B7: 46232 | C7: حملة فيسبوك - كتاب المعاصر | D7: فيسبوك | F7: 10800

Sheet الموظفين
B2: الموظفين والمرتبات والعمولات
B3: سجّل هنا أي موظف ومرتبه، وعمولته عن كل عميل يقفل الديل معاه - العدد والإجمالي بيتحسبوا لوحدهم من شيت الطلبات
B5: اسم الموظف | C5: الوظيفة | D5: الراتب الشهري | E5: العمولة عن كل عميل | F5: عدد العملاء اللي قفلهم | G5: إجمالي العمولة | H5: إجمالي المستحق (راتب+عمولة) | I5: إجمالي الرواتب + العمولات: | J5: =SUM(H6:H100) -> 11725 | K5: ملاحظات
B6: سارة علي | C6: خدمة عملاء ومبيعات (رد على واتساب وقفل الديل) | D6: 0 | E6: 5 | F6: =IF(B6="","",COUNTIF(الطلبات!$F$6:$F$200,B6)) -> 0 | G6: =IF(B6="","",E6*F6) -> 0 | H6: =IF(B6="","",D6+G6) -> 0 | I6: 01/08/2026 | J6: راتب ثابت + عمولة | K6: بتستلم كل استفسارات الواتساب
B7: مهند إبراهيم | D7: 10000 | E7: 25 | F7: =IF(B7="","",COUNTIF(الطلبات!$F$6:$F$200,B7)) -> 63 | G7: =IF(B7="","",E7*F7) -> 1575 | H7: =IF(B7="","",D7+G7) -> 11575
B8: السيد محمود | F8: =IF(B8="","",COUNTIF(الطلبات!$F$6:$F$200,B8)) -> 0 | G8: =IF(B8="","",E8*F8) -> 0 | H8: =IF(B8="","",D8+G8) -> 0
B9: محمد محمود | C9: تسليم عملاء | E9: 25 | F9: 6 | G9: =IF(B9="","",E9*F9) -> 150 | H9: =IF(B9="","",D9+G9) -> 150
F10: =IF(B10="","",COUNTIF(الطلبات!$F$6:$F$200,B10)) | G10: =IF(B10="","",E10*F10) | H10: =IF(B10="","",D10+G10)
F11: =IF(B11="","",COUNTIF(الطلبات!$F$6:$F$200,B11)) | G11: =IF(B11="","",E11*F11) | H11: =IF(B11="","",D11+G11)
F12: =IF(B12="","",COUNTIF(الطلبات!$F$6:$F$200,B12)) | G12: =IF(B12="","",E12*F12) | H12: =IF(B12="","",D12+G12)
F13: =IF(B13="","",COUNTIF(الطلبات!$F$6:$F$200,B13)) | G13: =IF(B13="","",E13*F13) | H13: =IF(B13="","",D13+G13)
F14: =IF(B14="","",COUNTIF(الطلبات!$F$6:$F$200,B14)) | G14: =IF(B14="","",E14*F14) | H14: =IF(B14="","",D14+G14)
F15: =IF(B15="","",COUNTIF(الطلبات!$F$6:$F$200,B15)) | G15: =IF(B15="","",E15*F15) | H15: =IF(B15="","",D15+G15)
F16: =IF(B16="","",COUNTIF(الطلبات!$F$6:$F$200,B16)) | G16: =IF(B16="","",E16*F16) | H16: =IF(B16="","",D16+G16)
F17: =IF(B17="","",COUNTIF(الطلبات!$F$6:$F$200,B17)) | G17: =IF(B17="","",E17*F17) | H17: =IF(B17="","",D17+G17)
F18: =IF(B18="","",COUNTIF(الطلبات!$F$6:$F$200,B18)) | G18: =IF(B18="","",E18*F18) | H18: =IF(B18="","",D18+G18)
F19: =IF(B19="","",COUNTIF(الطلبات!$F$6:$F$200,B19)) | G19: =IF(B19="","",E19*F19) | H19: =IF(B19="","",D19+G19)
F20: =IF(B20="","",COUNTIF(الطلبات!$F$6:$F$200,B20)) | G20: =IF(B20="","",E20*F20) | H20: =IF(B20="","",D20+G20)
F21: =IF(B21="","",COUNTIF(الطلبات!$F$6:$F$200,B21)) | G21: =IF(B21="","",E21*F21) | H21: =IF(B21="","",D21+G21)
... F100: =IF(B100="","",COUNTIF(الطلبات!$F$6:$F$200,B100)) | G100: =IF(B100="","",E100*F100) | H100: =IF(B100="","",D100+G100)
